<?xml version="1.0"?>
<robot name="robot_name">
    <link name="base_footprint">
        
    </link>
    <link name="base_link">
        <visual>
            <geometry>
                <box size="0.25 0.20 0.020"/>
            </geometry>
            <material name="red">
                <color rgba="1.0 0.0 0.0 1.0"/>
            </material>
        </visual>
    </link>
    <joint name="base_joint" type="fixed">
        <origin xyz="0.0 0.0 0.0" rpy="0.0 0.0 0.0"/>
        <parent link="base_footprint"/>
        <child link="base_link"/>
        <axis xyz="0.0 0.0 0.0"/>
        <limit lower="0.0" upper="0.0" effort="0.0" velocity="0.0"/>
    </joint>
    <link name="left_wheel">
        <visual>
            <geometry>
                <cylinder radius="0.05" length="0.05"/>
            </geometry>
            <material name="grey">
                <color rgba="0.5 0.5 0.5 1.0"/>
            </material>
        </visual>
    </link>
    <joint name="joint_left" type="revolute">
        <origin xyz="0.0 0.15 0.0" rpy="-1.57 0.0 0.0"/>
        <parent link="base_link"/>
        <child link="left_wheel"/>
        <axis xyz="0.0 0.0 1"/>
        <limit lower="-3.14" upper="3.14" effort="0.0" velocity="0.0"/>
    </joint>
</robot>